<?xml version="1.0" ?>
<!-- =================================================================================== -->
<!-- |    This document was autogenerated by xacro from /home/ikenta/ros2_ws/src/arm_wheel_robot_description/urdf/arm_wheel_robot.xacro | -->
<!-- |    EDITING THIS FILE BY HAND IS NOT RECOMMENDED                                 | -->
<!-- =================================================================================== -->
<robot name="arm_wheel_robot">
  <material name="silver">
    <color rgba="0.700 0.700 0.700 1.000"/>
  </material>
  

  <transmission name="shoulder_joint_tran">
    <type>transmission_interface/SimpleTransmission</type>
    <joint name="shoulder_joint">
      <hardwareInterface>hardware_interface/EffortJointInterface</hardwareInterface>
    </joint>
    <actuator name="shoulder_joint_actr">
      <hardwareInterface>hardware_interface/EffortJointInterface</hardwareInterface>
      <mechanicalReduction>1</mechanicalReduction>
    </actuator>
  </transmission>
  <transmission name="elbow_joint_tran">
    <type>transmission_interface/SimpleTransmission</type>
    <joint name="elbow_joint">
      <hardwareInterface>hardware_interface/EffortJointInterface</hardwareInterface>
    </joint>
    <actuator name="elbow_joint_actr">
      <hardwareInterface>hardware_interface/EffortJointInterface</hardwareInterface>
      <mechanicalReduction>1</mechanicalReduction>
    </actuator>
  </transmission>
  <transmission name="fan_joint_tran">
    <type>transmission_interface/SimpleTransmission</type>
    <joint name="fan_joint">
      <hardwareInterface>hardware_interface/EffortJointInterface</hardwareInterface>
    </joint>
    <actuator name="fan_joint_actr">
      <hardwareInterface>hardware_interface/EffortJointInterface</hardwareInterface>
      <mechanicalReduction>1</mechanicalReduction>
    </actuator>
  </transmission>
  <transmission name="left_wheel_joint_tran">
    <type>transmission_interface/SimpleTransmission</type>
    <joint name="left_wheel_joint">
      <hardwareInterface>hardware_interface/EffortJointInterface</hardwareInterface>
    </joint>
    <actuator name="left_wheel_joint_actr">
      <hardwareInterface>hardware_interface/EffortJointInterface</hardwareInterface>
      <mechanicalReduction>1</mechanicalReduction>
    </actuator>
  </transmission>
  <transmission name="right_wheel_joint_tran">
    <type>transmission_interface/SimpleTransmission</type>
    <joint name="right_wheel_joint">
      <hardwareInterface>hardware_interface/EffortJointInterface</hardwareInterface>
    </joint>
    <actuator name="right_wheel_joint_actr">
      <hardwareInterface>hardware_interface/EffortJointInterface</hardwareInterface>
      <mechanicalReduction>1</mechanicalReduction>
    </actuator>
  </transmission>
  

  <gazebo>
    <plugin filename="libgazebo_ros_control.so" name="control"/>
  </gazebo>
  <gazebo reference="body_link">
    <material>Gazebo/Silver</material>
    <mu1>0.2</mu1>
    <mu2>0.2</mu2>
    <selfCollide>true</selfCollide>
    <gravity>true</gravity>
  </gazebo>
  <gazebo reference="shoulder_base">
    <material>Gazebo/Silver</material>
    <mu1>0.2</mu1>
    <mu2>0.2</mu2>
    <selfCollide>true</selfCollide>
  </gazebo>
  <gazebo reference="shoulder_link">
    <material>Gazebo/Silver</material>
    <mu1>0.2</mu1>
    <mu2>0.2</mu2>
    <selfCollide>true</selfCollide>
  </gazebo>
  <gazebo reference="elbow_link">
    <material>Gazebo/Silver</material>
    <mu1>0.2</mu1>
    <mu2>0.2</mu2>
    <selfCollide>true</selfCollide>
  </gazebo>
  <gazebo reference="fancase_link">
    <material>Gazebo/Silver</material>
    <mu1>0.2</mu1>
    <mu2>0.2</mu2>
    <selfCollide>true</selfCollide>
  </gazebo>
  <gazebo reference="fan_link">
    <material>Gazebo/Silver</material>
    <mu1>0.2</mu1>
    <mu2>0.2</mu2>
    <selfCollide>true</selfCollide>
  </gazebo>
  <gazebo reference="left_wheel_link">
    <material>Gazebo/Silver</material>
    <mu1>0.2</mu1>
    <mu2>0.2</mu2>
    <selfCollide>true</selfCollide>
  </gazebo>
  <gazebo reference="right_wheel_link">
    <material>Gazebo/Silver</material>
    <mu1>0.2</mu1>
    <mu2>0.2</mu2>
    <selfCollide>true</selfCollide>
  </gazebo>
  <gazebo reference="linetrace_link">
    <material>Gazebo/Silver</material>
    <mu1>0.2</mu1>
    <mu2>0.2</mu2>
    <selfCollide>true</selfCollide>
  </gazebo>
  <gazebo reference="camera_link">
    <material>Gazebo/Silver</material>
    <mu1>0.2</mu1>
    <mu2>0.2</mu2>
    <selfCollide>true</selfCollide>
  </gazebo>
  
  <link name="base_link"/>

  <link name="body_link">
    <inertial>
      <origin rpy="0 0 0" xyz="0.038195858088118206 -0.00029293631873281086 0.048324553698934285"/>
      <mass value="0.9023939727730829"/>
      <inertia ixx="0.008694" ixy="-4.3e-05" ixz="-0.003025" iyy="0.01045" iyz="-1.6e-05" izz="0.012177"/>
    </inertial>
    <visual>
      <origin rpy="0 0 0" xyz="0 0 0"/>
      <geometry>
	      <mesh filename="file:///home/ikenta/ros2_ws/src/arm_detecting_controll/models/maze/meshes/body_link.stl" scale="0.001 0.001 0.001"/>
      </geometry>
      <material name="silver"/>
    </visual>
    <collision>
      <origin rpy="0 0 0" xyz="0 0 0"/>
      <geometry>
        <mesh filename="file:///home/ikenta/ros2_ws/src/arm_detecting_controll/models/maze/meshes/body_link.stl" scale="0.001 0.001 0.001"/>
      </geometry>
    </collision>
  </link>
  <link name="shoulder_base">
    <inertial>
      <origin rpy="0 0 0" xyz="-0.04190587157187109 -0.00499663473351941 0.03519660209760565"/>
      <mass value="0.04805535665511946"/>
      <inertia ixx="1.5e-05" ixy="0.0" ixz="5e-06" iyy="2.9e-05" iyz="-0.0" izz="1.8e-05"/>
    </inertial>
    <visual>
      <origin rpy="0 0 0" xyz="0.037271 -0.005 -0.0015"/>
      <geometry>
        <mesh filename="file:///home/ikenta/ros2_ws/src/arm_detecting_controll/models/maze/meshes/shoulder_base.stl" scale="0.001 0.001 0.001"/>
      </geometry>
      <material name="silver"/>
    </visual>
    <collision>
      <origin rpy="0 0 0" xyz="0.037271 -0.005 -0.0015"/>
      <geometry>
        <mesh filename="file:///home/ikenta/ros2_ws/src/arm_detecting_controll/models/maze/meshes/shoulder_base.stl" scale="0.001 0.001 0.001"/>
      </geometry>
    </collision>
  </link>
  <link name="shoulder_link">
    <inertial>
      <origin rpy="0 0 0" xyz="-0.0013498219810096496 2.7526660457015325e-05 0.07399861525014231"/>
      <mass value="0.11107447123195605"/>
      <inertia ixx="6.6e-05" ixy="-0.0" ixz="-7e-06" iyy="5.4e-05" iyz="0.0" izz="2.4e-05"/>
    </inertial>
    <visual>
      <origin rpy="0 0 0" xyz="0.098002 -5e-06 -0.0145"/>
      <geometry>
        <mesh filename="file:///home/ikenta/ros2_ws/src/arm_detecting_controll/models/maze/meshes/shoulder_link.stl" scale="0.001 0.001 0.001"/>
      </geometry>
      <material name="silver"/>
    </visual>
    <collision>
      <origin rpy="0 0 0" xyz="0.098002 -5e-06 -0.0145"/>
      <geometry>
        <mesh filename="file:///home/ikenta/ros2_ws/src/arm_detecting_controll/models/maze/meshes/shoulder_link.stl" scale="0.001 0.001 0.001"/>
      </geometry>
    </collision>
  </link>
  <link name="elbow_link">
    <inertial>
      <origin rpy="0 0 0" xyz="-2.234722377425502e-07 0.025499797788541737 0.09168304424634048"/>
      <mass value="0.10768771500759752"/>
      <inertia ixx="0.000377" ixy="0.0" ixz="0.0" iyy="0.000321" iyz="0.0" izz="6.4e-05"/>
    </inertial>
    <visual>
      <origin rpy="0 0 0" xyz="0.097997 0.025495 -0.104732"/>
      <geometry>
        <mesh filename="file:///home/ikenta/ros2_ws/src/arm_detecting_controll/models/maze/meshes/elbow_link.stl" scale="0.001 0.001 0.001"/>
      </geometry>
      <material name="silver"/>
    </visual>
    <collision>
      <origin rpy="0 0 0" xyz="0.097997 0.025495 -0.104732"/>
      <geometry>
        <mesh filename="file:///home/ikenta/ros2_ws/src/arm_detecting_controll/models/maze/meshes/elbow_link.stl" scale="0.001 0.001 0.001"/>
      </geometry>
    </collision>
  </link>
  
  <link name="fancase_link">
    <inertial>
      <origin rpy="0 0 0" xyz="-2.2349675751764941e-07 -2.022114521695582e-07 0.026653856022686162"/>
      <mass value="0.029214118817680147"/>
      <inertia ixx="2.9e-05" ixy="0.0" ixz="-0.0" iyy="2.9e-05" iyz="-0.0" izz="2.9e-05"/>
    </inertial>
    <visual>
      <origin rpy="0 0 0" xyz="0.097997 -5e-06 -0.282732"/>
      <geometry>
        <mesh filename="file:///home/ikenta/ros2_ws/src/arm_detecting_controll/models/maze/meshes/fancase_link.stl" scale="0.001 0.001 0.001"/>
      </geometry>
      <material name="silver"/>
    </visual>
    <collision>
      <origin rpy="0 0 0" xyz="0.097997 -5e-06 -0.282732"/>
      <geometry>
        <mesh filename="file:///home/ikenta/ros2_ws/src/arm_detecting_controll/models/maze/meshes/fancase_link.stl" scale="0.001 0.001 0.001"/>
      </geometry>
    </collision>
  </link>
  <link name="fan_link">
    <inertial>
      <origin rpy="0 0 0" xyz="-2.234967574343827e-07 -2.0221145213846615e-07 0.0044871539729533505"/>
      <mass value="0.019203927572863683"/>
      <inertia ixx="5e-06" ixy="0.0" ixz="0.0" iyy="5e-06" iyz="-0.0" izz="9e-06"/>
    </inertial>
    <visual>
      <origin rpy="0 0 0" xyz="0.097997 -5e-06 -0.285732"/>
      <geometry>
        <mesh filename="file:///home/ikenta/ros2_ws/src/arm_detecting_controll/models/maze/meshes/fan_link.stl" scale="0.001 0.001 0.001"/>
      </geometry>
      <material name="silver"/>
    </visual>
    <collision>
      <origin rpy="0 0 0" xyz="0.097997 -5e-06 -0.285732"/>
      <geometry>
        <mesh filename="file:///home/ikenta/ros2_ws/src/arm_detecting_controll/models/maze/meshes/fan_link.stl" scale="0.001 0.001 0.001"/>
      </geometry>
    </collision>
  </link>
  
  <link name="left_wheel_link">
    <inertial>
      <origin rpy="0 0 0" xyz="-8.326672684688674e-17 0.0024999999999999745 -4.0314973581701e-15"/>
      <mass value="0.00940172683347289"/>
      <inertia ixx="1e-06" ixy="0.0" ixz="0.0" iyy="3e-06" iyz="-0.0" izz="1e-06"/>
    </inertial>
    <visual>
      <origin rpy="0 0 0" xyz="0.13 0.1445 0.0225"/>
      <geometry>
        <mesh filename="file:///home/ikenta/ros2_ws/src/arm_detecting_controll/models/maze/meshes/left_wheel_link.stl" scale="0.001 0.001 0.001"/>
      </geometry>
      <material name="silver"/>
    </visual>
    <collision>
      <origin rpy="0 0 0" xyz="0.13 0.1445 0.0225"/>
      <geometry>
        <mesh filename="file:///home/ikenta/ros2_ws/src/arm_detecting_controll/models/maze/meshes/left_wheel_link.stl" scale="0.001 0.001 0.001"/>
      </geometry>
    </collision>
  </link>
  <link name="right_wheel_link">
    <inertial>
      <origin rpy="0 0 0" xyz="1.1102230246251565e-16 -0.0025000000000000577 -4.0245584642661925e-15"/>
      <mass value="0.00940172683347289"/>
      <inertia ixx="1e-06" ixy="-0.0" ixz="-0.0" iyy="3e-06" iyz="0.0" izz="1e-06"/>
    </inertial>
    <visual>
      <origin rpy="0 0 0" xyz="0.13 -0.1445 0.0225"/>
      <geometry>
        <mesh filename="file:///home/ikenta/ros2_ws/src/arm_detecting_controll/models/maze/meshes/right_wheel_link.stl" scale="0.001 0.001 0.001"/>
      </geometry>
      <material name="silver"/>
    </visual>
    <collision>
      <origin rpy="0 0 0" xyz="0.13 -0.1445 0.0225"/>
      <geometry>
        <mesh filename="file:///home/ikenta/ros2_ws/src/arm_detecting_controll/models/maze/meshes/right_wheel_link.stl" scale="0.001 0.001 0.001"/>
      </geometry>
    </collision>
  </link>

  <link name="linetrace_link">
    <inertial>
      <origin rpy="0 0 0" xyz="-0.006639441767623655 0.050000000000000155 -0.0010000000000000286"/>
      <mass value="0.005248538060524059"/>
      <inertia ixx="7e-06" ixy="-0.0" ixz="0.0" iyy="0.0" iyz="0.0" izz="7e-06"/>
    </inertial>
    <visual>
      <origin rpy="0 0 0" xyz="0.139 0.05 0.0445"/>
      <geometry>
        <mesh filename="file:///home/ikenta/ros2_ws/src/arm_detecting_controll/models/maze/meshes/linetrace_link.stl" scale="0.001 0.001 0.001"/>
      </geometry>
      <material name="silver"/>
    </visual>
    <collision>
      <origin rpy="0 0 0" xyz="0.139 0.05 0.0445"/>
      <geometry>
        <mesh filename="file:///home/ikenta/ros2_ws/src/arm_detecting_controll/models/maze/meshes/linetrace_link.stl" scale="0.001 0.001 0.001"/>
      </geometry>
    </collision>
  </link>
  <link name="linetrace_link2">
    <visual>
      <geometry>
        <box size="0.002 0.002 0.002"/>
      </geometry>
      <material name="blue"/>
    </visual>
    <collision>
      <geometry>
        <box size="0.002 0.002 0.002"/>
      </geometry>
    </collision>
    <inertial>
      <mass value="0.0001"/>
      <inertia ixx="0.0001" ixy="0.0" ixz="0.0" iyy="0.0001" iyz="0.0" izz="0.0001"/>
    </inertial>
  </link>

  <link name="linetrace_link3">
    <visual>
      <geometry>
        <box size="0.002 0.002 0.002"/>
      </geometry>
      <material name="blue"/>
    </visual>
    <collision>
      <geometry>
        <box size="0.002 0.002 0.002"/>
      </geometry>
    </collision>
    <inertial>
      <mass value="0.0001"/>
      <inertia ixx="0.0001" ixy="0.0" ixz="0.0" iyy="0.0001" iyz="0.0" izz="0.0001"/>
    </inertial>
  </link>

  <link name="linetrace_link4">
    <visual>
      <geometry>
        <box size="0.002 0.002 0.002"/>
      </geometry>
      <material name="blue"/>
    </visual>
    <collision>
      <geometry>
        <box size="0.002 0.002 0.002"/>
      </geometry>
    </collision>
    <inertial>
      <mass value="0.0001"/>
      <inertia ixx="0.0001" ixy="0.0" ixz="0.0" iyy="0.0001" iyz="0.0" izz="0.0001"/>
    </inertial>
  </link>

  <link name="linetrace_link5">
    <visual>
      <geometry>
        <box size="0.002 0.002 0.002"/>
      </geometry>
      <material name="blue"/>
    </visual>
    <collision>
      <geometry>
        <box size="0.002 0.002 0.002"/>
      </geometry>
    </collision>
    <inertial>
      <mass value="0.0001"/>
      <inertia ixx="0.0001" ixy="0.0" ixz="0.0" iyy="0.0001" iyz="0.0" izz="0.0001"/>
    </inertial>
  </link>

  <link name="camera_link">
    <inertial>
      <origin rpy="0 0 0" xyz="-0.02040548444245127 -3.122502256758253e-17 0.007000000000000018"/>
      <mass value="0.06369938289373575"/>
      <inertia ixx="1.9e-05" ixy="0.0" ixz="0.0" iyy="3.8e-05" iyz="0.0" izz="5.2e-05"/>
    </inertial>
    <visual>
      <origin rpy="0 0 0" xyz="0.1235 0.02 0.0165"/>
      <geometry>
        <mesh filename="file:///home/ikenta/ros2_ws/src/arm_detecting_controll/models/maze/meshes/camera_link.stl" scale="0.001 0.001 0.001"/>
      </geometry>
      <material name="silver"/>
    </visual>
    <collision>
      <origin rpy="0 0 0" xyz="0.1235 0.02 0.0165"/>
      <geometry>
        <mesh filename="file:///home/ikenta/ros2_ws/src/arm_detecting_controll/models/maze/meshes/camera_link.stl" scale="0.001 0.001 0.001"/>
      </geometry>
    </collision>
  </link>
  <link name="camera_frame_link">
    <visual>
      <geometry>
        <box size="0.0002 0.0002 0.0002"/>
      </geometry>
      <material name="blue"/>
    </visual>
    <collision>
      <geometry>
        <box size="0.0002 0.0002 0.0002"/>
      </geometry>
    </collision>
    <inertial>
      <mass value="0.0001"/>
      <inertia ixx="0.0001" ixy="0.0" ixz="0.0" iyy="0.0001" iyz="0.0" izz="0.0001"/>
    </inertial>
  </link>

  <joint name="body_joint" type="fixed">
    <origin rpy="0 0 0" xyz="0 0 0.5"/>
    <parent link="base_link"/>
    <child link="body_link"/>
  </joint>

  <joint name="shoulder_base_joint" type="fixed">
    <origin rpy="0 0 0" xyz="-0.037271 0.005 0.0015"/>
    <parent link="body_link"/>
    <child link="shoulder_base"/>
  </joint>
  <joint name="shoulder_joint" type="revolute">
    <origin rpy="0 0 0" xyz="-0.060731 -0.004995 0.013"/>
    <parent link="shoulder_base"/>
    <child link="shoulder_link"/>
    <axis xyz="1.0 0.0 0.0"/>
    <limit effort="100" lower="-1.047198" upper="1.047198" velocity="100"/>
  </joint>
  <joint name="elbow_joint" type="revolute">
    <origin rpy="0 0 0" xyz="5e-06 -0.0255 0.090232"/>
    <parent link="shoulder_link"/>
    <child link="elbow_link"/>
    <axis xyz="0.0 -1.0 -0.0"/>
    <limit effort="100" lower="-0.872665" upper="2.181662" velocity="100"/>
  </joint>
  
  <joint name="fancase_joint" type="fixed">
    <origin rpy="0 0 0" xyz="0.0 0.0255 0.178"/>
    <parent link="elbow_link"/>
    <child link="fancase_link"/>
  </joint>
  <joint name="fan_joint" type="continuous">
    <origin rpy="0 0 0" xyz="0.0 0.0 0.003"/>
    <parent link="fancase_link"/>
    <child link="fan_link"/>
    <axis xyz="-0.0 0.0 -1.0"/>
  </joint>
  
  <joint name="left_wheel_joint" type="continuous">
    <origin rpy="0 0 1.5708" xyz="-0.13 -0.1445 -0.0225"/>
    <parent link="body_link"/>
    <child link="left_wheel_link"/>
    <axis xyz="-0.0 -1.0 -0.0"/>
  </joint>
  <joint name="right_wheel_joint" type="continuous">
    <origin rpy="0 0 0" xyz="-0.13 0.1445 -0.0225"/>
    <parent link="body_link"/>
    <child link="right_wheel_link"/>
    <axis xyz="0.0 1.0 0.0"/>
  </joint>

  <joint name="linetrace_joint" type="fixed">
    <origin rpy="0 0 0" xyz="-0.139 -0.05 -0.0445"/>
    <parent link="body_link"/>
    <child link="linetrace_link"/>
  </joint>
  <joint name="linetrace_joint2" type="fixed">
    <origin xyz="-0.01 -0.074 -0.002" rpy="0 1.5708 0"/>
    <parent link="linetrace_link"/>
    <child link="linetrace_link2"/>
  </joint>
  <joint name="linetrace_joint3" type="fixed">
    <origin xyz="-0.01 -0.058 -0.002" rpy="0 1.5708 0"/>
    <parent link="linetrace_link"/>
    <child link="linetrace_link3"/>
  </joint>

  <joint name="linetrace_joint4" type="fixed">
    <origin xyz="-0.01 -0.042 -0.002" rpy="0 1.5708 0"/>
    <parent link="linetrace_link"/>
    <child link="linetrace_link4"/>
  </joint>
  <joint name="linetrace_joint5" type="fixed">
    <origin xyz="-0.01 -0.026 -0.002" rpy="0 1.5708 0"/>
    <parent link="linetrace_link"/>
    <child link="linetrace_link5"/>
  </joint>

  <joint name="camera_joint" type="fixed">
    <origin rpy="0 0 0" xyz="-0.1235 -0.02 -0.0165"/>
    <parent link="body_link"/>
    <child link="camera_link"/>
  </joint>
  <joint name="camera_frame_joint" type="fixed">
    <origin rpy="0 0 3.1416" xyz="-0.047 0.019 0.006"/>
    <parent link="camera_link"/>
    <child link="camera_frame_link"/>
  </joint>


  <gazebo>
    <plugin filename="libgazebo_ros2_control.so" name="gazebo_ros2_control">
      <robot_sim_type>gazebo_ros2_control/GazeboSystem</robot_sim_type>
      <parameters>/home/ikenta/ros2_ws/src/arm_detecting_controll/config/rdc_arm.yaml</parameters>
    </plugin>
  </gazebo>

  <ros2_control name="GazeboSystem" type="system">
    <hardware>
      <plugin>gazebo_ros2_control/GazeboSystem</plugin>
    </hardware>
    <joint name="shoulder_joint">
      <command_interface name="position">
        <param name="min">-3.14</param>
        <param name="max">3.14</param>
      </command_interface>
      <command_interface name="velocity">
        <param name="min">-3.15</param>
        <param name="max">3.15</param>
      </command_interface>
      <state_interface name="position"/>
      <state_interface name="velocity"/>
      <state_interface name="effort"/>
      <param name="initial_position">0.0</param>
    </joint>
    <joint name="elbow_joint">
      <command_interface name="position">
        <param name="min">-3.14</param>
        <param name="max">3.14</param>
      </command_interface>
      <command_interface name="velocity">
        <param name="min">-3.15</param>
        <param name="max">3.15</param>
      </command_interface>
      <state_interface name="position"/>
      <state_interface name="velocity"/>
      <state_interface name="effort"/>
      <param name="initial_position">0.0</param>
    </joint>
    <joint name="left_wheel_joint">
      <command_interface name="velocity"/>
      <state_interface name="velocity"/>
    </joint>

    <joint name="right_wheel_joint">
      <command_interface name="velocity"/>
      <state_interface name="velocity"/>
    </joint>
  </ros2_control>

  <gazebo reference="camera_frame_link">
    <sensor name="camera_sensor" type="camera">
      <always_on>true</always_on>
      <update_rate>30.0</update_rate>
      <visualize>true</visualize>
      <camera>
        <horizontal_fov>0.9599</horizontal_fov>
        <image>
          <width>640</width>
          <height>480</height>
          <format>R8G8B8</format>
        </image>
        <clip>
          <near>0.1</near>
          <far>100</far>
        </clip>
      </camera>
      <plugin name="camera_controller" filename="libgazebo_ros_camera.so">
        <ros>
          <namespace>/wheel_robot_simple</namespace>
        </ros>
        <camera_name>camera</camera_name>
        <image_topic_name>image_raw</image_topic_name>
        <camera_info_topic_name>camera_info</camera_info_topic_name>
        <frame_name>camera_frame_link</frame_name>
      </plugin>
    </sensor>
  </gazebo>

  <gazebo reference="linetrace_link2">
    <sensor name="linetrace_sensor2" type="camera">
      <always_on>true</always_on>
      <update_rate>30.0</update_rate>
      <visualize>true</visualize>
      <camera>
        <horizontal_fov>0.1745</horizontal_fov>
        <image>
          <width>320</width>
          <height>240</height>
          <format>R8G8B8</format>
        </image>
        <clip>
          <near>0.001</near>
          <far>0.05</far>
        </clip>
      </camera>
      <plugin name="linetrace_sensor2" filename="libgazebo_ros_camera.so">
        <ros>
          <namespace>/wheel_robot_simple</namespace>
        </ros>
        <camera_name>linetrace2</camera_name>
        <image_topic_name>linetrace2/image_raw</image_topic_name>
        <camera_info_topic_name>linetrace2/camera_info</camera_info_topic_name>
        <frame_name>linetrace_link2</frame_name>
      </plugin>
    </sensor>
  </gazebo>

  <gazebo reference="linetrace_link3">
    <sensor name="linetrace_sensor3" type="camera">
      <always_on>true</always_on>
      <update_rate>30.0</update_rate>
      <visualize>true</visualize>
      <camera>
        <horizontal_fov>0.1745</horizontal_fov>
        <image>
          <width>320</width>
          <height>240</height>
          <format>R8G8B8</format>
        </image>
        <clip>
          <near>0.001</near>
          <far>0.05</far>
        </clip>
      </camera>
      <plugin name="linetrace_sensor3" filename="libgazebo_ros_camera.so">
        <ros>
          <namespace>/wheel_robot_simple</namespace>
        </ros>
        <camera_name>linetrace3</camera_name>
        <image_topic_name>linetrace3/image_raw</image_topic_name>
        <camera_info_topic_name>linetrace3/camera_info</camera_info_topic_name>
        <frame_name>linetrace_link3</frame_name>
      </plugin>
    </sensor>
  </gazebo>

  <gazebo reference="linetrace_link4">
    <sensor name="linetrace_sensor4" type="camera">
      <always_on>true</always_on>
      <update_rate>30.0</update_rate>
      <visualize>true</visualize>
      <camera>
        <horizontal_fov>0.1745</horizontal_fov>
        <image>
          <width>320</width>
          <height>240</height>
          <format>R8G8B8</format>
        </image>
        <clip>
          <near>0.001</near>
          <far>0.05</far>
        </clip>
      </camera>
      <plugin name="linetrace_sensor4" filename="libgazebo_ros_camera.so">
        <ros>
          <namespace>/wheel_robot_simple</namespace>
        </ros>
        <camera_name>linetrace4</camera_name>
        <image_topic_name>linetrace4/image_raw</image_topic_name>
        <camera_info_topic_name>linetrace4/camera_info</camera_info_topic_name>
        <frame_name>linetrace_link4</frame_name>
      </plugin>
    </sensor>
  </gazebo>

  <gazebo reference="linetrace_link5">
    <sensor name="linetrace_sensor5" type="camera">
      <always_on>true</always_on>
      <update_rate>30.0</update_rate>
      <visualize>true</visualize>
      <camera>
        <horizontal_fov>0.1745</horizontal_fov>
        <image>
          <width>320</width>
          <height>240</height>
          <format>R8G8B8</format>
        </image>
        <clip>
          <near>0.001</near>
          <far>0.05</far>
        </clip>
      </camera>
      <plugin name="linetrace_sensor5" filename="libgazebo_ros_camera.so">
        <ros>
          <namespace>/wheel_robot_simple</namespace>
        </ros>
        <camera_name>linetrace5</camera_name>
        <image_topic_name>linetrace5/image_raw</image_topic_name>
        <camera_info_topic_name>linetrace5/camera_info</camera_info_topic_name>
        <frame_name>linetrace_link5</frame_name>
      </plugin>
    </sensor>
  </gazebo>

  <gazebo reference="fancase_link">
    <plugin name="vacuum_gripper" filename="libgazebo_ros_vacuum_gripper.so">
      <ros>
        <namespace>/vacuum_gripper</namespace>
      </ros>
      <link_name>fancase_link</link_name>
      <max_force>1000</max_force>
      <max_distance>200.0</max_distance>
    </plugin>
  </gazebo>

</robot>
